<?xml version="1.0"?>
<robot name="sample_6dof_arm">
  <link name="base_link"/>
  <link name="shoulder_link"/>
  <link name="upper_arm_link"/>
  <link name="forearm_link"/>
  <link name="wrist_1_link"/>
  <link name="wrist_2_link"/>
  <link name="wrist_3_link"/>

  <joint name="joint_1" type="revolute">
    <parent link="base_link"/>
    <child link="shoulder_link"/>
    <origin xyz="0 0 0.35" rpy="0 0 0"/>
    <axis xyz="0 0 1"/>
  </joint>
  <joint name="joint_2" type="revolute">
    <parent link="shoulder_link"/>
    <child link="upper_arm_link"/>
    <origin xyz="0 0 0.25" rpy="0 1.5708 0"/>
    <axis xyz="0 1 0"/>
  </joint>
  <joint name="joint_3" type="revolute">
    <parent link="upper_arm_link"/>
    <child link="forearm_link"/>
    <origin xyz="0.35 0 0" rpy="0 0 0"/>
    <axis xyz="0 1 0"/>
  </joint>
  <joint name="joint_4" type="revolute">
    <parent link="forearm_link"/>
    <child link="wrist_1_link"/>
    <origin xyz="0.30 0 0" rpy="0 0 0"/>
    <axis xyz="1 0 0"/>
  </joint>
  <joint name="joint_5" type="revolute">
    <parent link="wrist_1_link"/>
    <child link="wrist_2_link"/>
    <origin xyz="0.18 0 0" rpy="0 0 0"/>
    <axis xyz="0 1 0"/>
  </joint>
  <joint name="joint_6" type="revolute">
    <parent link="wrist_2_link"/>
    <child link="wrist_3_link"/>
    <origin xyz="0.12 0 0" rpy="0 0 0"/>
    <axis xyz="1 0 0"/>
  </joint>
</robot>
